Workbook

Sheet Cronograma
A1: CRONOGRAMA DE VISITAS PARA LA DIAGRAMACIÓN DE PROCESOS
A2: Facultad de Psicología (FPSIC) · Fase 2: documentación y diagramación de procedimientos (Grupo 1)
A3: Universidad Nacional Mayor de San Marcos · Oficina General de Planificación · Oficina de Racionalización | Proyecto P01 · Plan P01-PG-F2 v1.1 | Versión 2.0 del cronograma · revisada el 15/10/2026
A5: Sesiones de levantamiento | D5: Procesos | H5: Días de visita | J5: Horas de sesión | K5: Primera visita | L5: Última visita | O5: Sesiones sin confirmar
A6: =COUNTIF($H$11:$H$45,"?*") -> 30 | D6: =SUMPRODUCT(($H$11:$H$45<>"")/COUNTIF($H$11:$H$45,$H$11:$H$45&"")) -> 15 | H6: =SUMPRODUCT(($H$11:$H$45<>"")/(COUNTIFS($C$11:$C$45,$C$11:$C$45,$H$11:$H$45,"?*")+($H$11:$H$45=""))) -> 12 | J6: =SUM($G$11:$G$45)*24 -> 47.5 | K6: =_xlfn.MINIFS($C$11:$C$45,$H$11:$H$45,"?*") -> 46316 | L6: =_xlfn.MAXIFS($C$11:$C$45,$H$11:$H$45,"?*") -> 46337 | O6: =COUNTIFS($H$11:$H$45,"?*",$Q$11:$Q$45,"<>Confirmado") -> 0
A8: REUNIÓN DE APERTURA Con la Decana y los jefes de las unidades orgánicas · Martes 20/10/2026 · 09:00 a 10:00 · Sala de Sesiones de la FPSIC | J8: REQUISITO PARA CADA REUNIÓN · La jefatura o su representante relata, el día de la reunión, únicamente la secuencia de pasos que sigue en su día a día para llevar a cabo el procedimiento, y asiste con los documentos que usa en su labor diaria (directivas, instructivos o manuales).
A10: N.º | B10: Visita | C10: Fecha | D10: Día | E10: Inicio | F10: Fin | G10: Duración | H10: Código | I10: Proceso | J10: Unidad orgánica | K10: Responsable | L10: Lugar | M10: Modalidad | N10: Enlace alterno (caso de fuerza mayor) | O10: Equipo OGPL (A: arquitecto · M: modelador · D: documentador) | P10: Bloque | Q10: Confirmación | R10: Observaciones
A11: OCTUBRE 2026
A12: =IF(H12="","",COUNTIF($H$11:H12,"?*")) -> 1 | B12: 1.ª visita | C12: 46316 | D12: =IF(C12="","",CHOOSE(WEEKDAY(C12,2),"Lunes","Martes","Miércoles","Jueves","Viernes","Sábado","Domingo")) -> Miércoles | E12: 0.39583333 | F12: 0.46527778 | G12: =IF(AND(E12<>"",F12<>""),F12-E12,"") -> 0.069444444 | H12: PE.01 | I12: Gestión Estratégica | J12: Jefatura de la Unidad de Planificación, Presupuesto y Racionalización (UPPR) | K12: Rosa Guillermina Coaila Moreno | L12: Sala de Alfombrado | M12: Presencial | N12: Google Meet | O12: =IF(P12="","","A: "&INDEX('Equipo y roles'!$C$13:$C$16,P12)&CHAR(10)&"M: "&INDEX('Equipo y roles'!$D$13:$D$16,P12)&CHAR(10)&"D: "&INDEX('Equipo y roles'!$E$13:$E$16,P12)) -> A: Alvaro Rojas Carnero M: Isabel Flores Huamaní D: Oriol Romero Saavedra | P12: 1 | Q12: Confirmado | R12: [Fila 7 del original]
A13: =IF(H13="","",COUNTIF($H$11:H13,"?*")) -> 2 | B13: 1.ª visita | C13: 46316 | D13: =IF(C13="","",CHOOSE(WEEKDAY(C13,2),"Lunes","Martes","Miércoles","Jueves","Viernes","Sábado","Domingo")) -> Miércoles | E13: 0.47222222 | F13: 0.54166667 | G13: =IF(AND(E13<>"",F13<>""),F13-E13,"") -> 0.069444444 | H13: PE.02 | I13: Gestión de la Calidad y Mejora Continua | J13: Jefatura de la Oficina de Calidad Académica y Acreditación | K13: Susana Consuelo Roggero Rebaza | L13: Sala de Alfombrado | M13: Presencial | N13: Google Meet | O13: =IF(P13="","","A: "&INDEX('Equipo y roles'!$C$13:$C$16,P13)&CHAR(10)&"M: "&INDEX('Equipo y roles'!$D$13:$D$16,P13)&CHAR(10)&"D: "&INDEX('Equipo y roles'!$E$13:$E$16,P13)) -> A: Alvaro Rojas Carnero M: Isabel Flores Huamaní D: Oriol Romero Saavedra | P13: 1 | Q13: Confirmado | R13: [Fila 8 del original]
A14: =IF(H14="","",COUNTIF($H$11:H14,"?*")) -> 3 | B14: 1.ª visita | C14: 46316 | D14: =IF(C14="","",CHOOSE(WEEKDAY(C14,2),"Lunes","Martes","Miércoles","Jueves","Viernes","Sábado","Domingo")) -> Miércoles | E14: 0.60416667 | F14: 0.67361111 | G14: =IF(AND(E14<>"",F14<>""),F14-E14,"") -> 0.069444444 | H14: PE.03 | I14: Gestión de Relaciones Interinstitucionales | J14: Dirección de la Escuela Profesional de Psicología Dirección de la Escuela Profesional de Psicología Organizacional y de la Gestión Humana Jefatura de la Unidad de Prácticas Preprofesionales | K14: Carmen Leni Alvarez Taco Abel Cuzcano Zapata Jorge Luis Soto Mateo | L14: Sala de Alfombrado | M14: Presencial | N14: Google Meet | O14: =IF(P14="","","A: "&INDEX('Equipo y roles'!$C$13:$C$16,P14)&CHAR(10)&"M: "&INDEX('Equipo y roles'!$D$13:$D$16,P14)&CHAR(10)&"D: "&INDEX('Equipo y roles'!$E$13:$E$16,P14)) -> A: Alvaro Rojas Carnero M: Isabel Flores Huamaní D: Oriol Romero Saavedra | P14: 1 | Q14: Confirmado | R14: Sesión conjunta. Abel Cuzcano hasta las 16:10; Carmen Alvarez y Jorge Soto hasta las 15:45 (como en el original). [Fila 9–11 del original]
A15: =IF(H15="","",COUNTIF($H$11:H15,"?*")) -> 4 | B15: 1.ª visita | C15: 46317 | D15: =IF(C15="","",CHOOSE(WEEKDAY(C15,2),"Lunes","Martes","Miércoles","Jueves","Viernes","Sábado","Domingo")) -> Jueves | E15: 0.39583333 | F15: 0.46527778 | G15: =IF(AND(E15<>"",F15<>""),F15-E15,"") -> 0.069444444 | H15: PM.01 | I15: Gestión de la Formación Académica | J15: Vicedecanato Académico de Pregrado | K15: Elisa Beatriz Yanac Reynoso | L15: Sala de Alfombrado | M15: Presencial | N15: Google Meet | O15: =IF(P15="","","A: "&INDEX('Equipo y roles'!$C$13:$C$16,P15)&CHAR(10)&"M: "&INDEX('Equipo y roles'!$D$13:$D$16,P15)&CHAR(10)&"D: "&INDEX('Equipo y roles'!$E$13:$E$16,P15)) -> A: Alvaro Rojas Carnero M: Isabel Flores Huamaní D: Oriol Romero Saavedra | P15: 1 | Q15: Confirmado | R15: [Fila 12 del original]
A16: =IF(H16="","",COUNTIF($H$11:H16,"?*")) -> 5 | B16: 1.ª visita | C16: 46317 | D16: =IF(C16="","",CHOOSE(WEEKDAY(C16,2),"Lunes","Martes","Miércoles","Jueves","Viernes","Sábado","Domingo")) -> Jueves | E16: 0.47222222 | F16: 0.54166667 | G16: =IF(AND(E16<>"",F16<>""),F16-E16,"") -> 0.069444444 | H16: PM.02 | I16: Gestión de la Investigación | J16: Vicedecanato de Investigación y Posgrado | K16: Carlos Alberto Arenas Iparraguirre | L16: Sala de Alfombrado | M16: Presencial | N16: Google Meet | O16: =IF(P16="","","A: "&INDEX('Equipo y roles'!$C$13:$C$16,P16)&CHAR(10)&"M: "&INDEX('Equipo y roles'!$D$13:$D$16,P16)&CHAR(10)&"D: "&INDEX('Equipo y roles'!$E$13:$E$16,P16)) -> A: Alvaro Rojas Carnero M: Isabel Flores Huamaní D: Oriol Romero Saavedra | P16: 1 | Q16: Confirmado | R16: [Fila 13 del original]
A17: =IF(H17="","",COUNTIF($H$11:H17,"?*")) -> 6 | B17: 1.ª visita | C17: 46317 | D17: =IF(C17="","",CHOOSE(WEEKDAY(C17,2),"Lunes","Martes","Miércoles","Jueves","Viernes","Sábado","Domingo")) -> Jueves | E17: 0.60416667 | F17: 0.65625 | G17: =IF(AND(E17<>"",F17<>""),F17-E17,"") -> 0.052083333 | H17: PM.03 | I17: Gestión de la Responsabilidad y Vinculación Social | J17: Jefatura del Centro de Responsabilidad Social y Extensión Universitaria | K17: Carmen Magali Meléndez Jara | L17: Sala de Alfombrado | M17: Presencial | N17: Google Meet | O17: =IF(P17="","","A: "&INDEX('Equipo y roles'!$C$13:$C$16,P17)&CHAR(10)&"M: "&INDEX('Equipo y roles'!$D$13:$D$16,P17)&CHAR(10)&"D: "&INDEX('Equipo y roles'!$E$13:$E$16,P17)) -> A: Alvaro Rojas Carnero M: Isabel Flores Huamaní D: Oriol Romero Saavedra | P17: 1 | Q17: Confirmado | R17: [Fila 14 del original]
A18: =IF(H18="","",COUNTIF($H$11:H18,"?*")) | B18: Equipo | C18: 46321 | D18: =IF(C18="","",CHOOSE(WEEKDAY(C18,2),"Lunes","Martes","Miércoles","Jueves","Viernes","Sábado","Domingo")) -> Lunes | I18: Reunión de coordinación del equipo · no se levantan diagramaciones | L18: Por definir | R18: Reunión programada con el equipo. Ese día no se levantan diagramaciones. [Fila 15 del original]
A19: =IF(H19="","",COUNTIF($H$11:H19,"?*")) -> 7 | B19: 1.ª visita | C19: 46322 | D19: =IF(C19="","",CHOOSE(WEEKDAY(C19,2),"Lunes","Martes","Miércoles","Jueves","Viernes","Sábado","Domingo")) -> Martes | E19: 0.39583333 | F19: 0.46527778 | G19: =IF(AND(E19<>"",F19<>""),F19-E19,"") -> 0.069444444 | H19: PS.01 | I19: Gestión de Admisión y Matrícula | J19: Vicedecanato Académico de Pregrado | K19: Elisa Beatriz Yanac Reynoso | L19: Sala de Alfombrado | M19: Presencial | N19: Google Meet | O19: =IF(P19="","","A: "&INDEX('Equipo y roles'!$C$13:$C$16,P19)&CHAR(10)&"M: "&INDEX('Equipo y roles'!$D$13:$D$16,P19)&CHAR(10)&"D: "&INDEX('Equipo y roles'!$E$13:$E$16,P19)) -> A: Isabel Flores Huamaní M: Oriol Romero Saavedra D: Leomar Bonzano Chavez | P19: 2 | Q19: Confirmado | R19: [Fila 16 del original]
A20: =IF(H20="","",COUNTIF($H$11:H20,"?*")) -> 8 | B20: 1.ª visita | C20: 46322 | D20: =IF(C20="","",CHOOSE(WEEKDAY(C20,2),"Lunes","Martes","Miércoles","Jueves","Viernes","Sábado","Domingo")) -> Martes | E20: 0.47222222 | F20: 0.54166667 | G20: =IF(AND(E20<>"",F20<>""),F20-E20,"") -> 0.069444444 | H20: PS.02 | I20: Gestión Documental | J20: Jefatura de la Unidad de Trámite Documentario y Archivo | K20: Edith Maribel Collins García | L20: Sala de Alfombrado | M20: Presencial | N20: Google Meet | O20: =IF(P20="","","A: "&INDEX('Equipo y roles'!$C$13:$C$16,P20)&CHAR(10)&"M: "&INDEX('Equipo y roles'!$D$13:$D$16,P20)&CHAR(10)&"D: "&INDEX('Equipo y roles'!$E$13:$E$16,P20)) -> A: Isabel Flores Huamaní M: Oriol Romero Saavedra D: Leomar Bonzano Chavez | P20: 2 | Q20: Confirmado | R20: [Fila 17 del original]
A21: =IF(H21="","",COUNTIF($H$11:H21,"?*")) -> 9 | B21: 1.ª visita | C21: 46322 | D21: =IF(C21="","",CHOOSE(WEEKDAY(C21,2),"Lunes","Martes","Miércoles","Jueves","Viernes","Sábado","Domingo")) -> Martes | E21: 0.60416667 | F21: 0.65625 | G21: =IF(AND(E21<>"",F21<>""),F21-E21,"") -> 0.052083333 | H21: PS.03 | I21: Gestión de Bienestar Integral | J21: Jefatura de la Unidad de Bienestar | K21: Rosa Digna Luna Pérez | L21: Sala de Alfombrado | M21: Presencial | N21: Google Meet | O21: =IF(P21="","","A: "&INDEX('Equipo y roles'!$C$13:$C$16,P21)&CHAR(10)&"M: "&INDEX('Equipo y roles'!$D$13:$D$16,P21)&CHAR(10)&"D: "&INDEX('Equipo y roles'!$E$13:$E$16,P21)) -> A: Isabel Flores Huamaní M: Oriol Romero Saavedra D: Leomar Bonzano Chavez | P21: 2 | Q21: Confirmado | R21: [Fila 18 del original]
A22: =IF(H22="","",COUNTIF($H$11:H22,"?*")) -> 10 | B22: 1.ª visita | C22: 46323 | D22: =IF(C22="","",CHOOSE(WEEKDAY(C22,2),"Lunes","Martes","Miércoles","Jueves","Viernes","Sábado","Domingo")) -> Miércoles | E22: 0.39583333 | F22: 0.46527778 | G22: =IF(AND(E22<>"",F22<>""),F22-E22,"") -> 0.069444444 | H22: PS.04 | I22: Gestión de Recursos Económicos | J22: Jefatura de la Unidad de Economía | K22: Nestor Felipe Chalque Alvarez | L22: Aula 7D (4.° piso) | M22: Presencial | N22: Google Meet | O22: =IF(P22="","","A: "&INDEX('Equipo y roles'!$C$13:$C$16,P22)&CHAR(10)&"M: "&INDEX('Equipo y roles'!$D$13:$D$16,P22)&CHAR(10)&"D: "&INDEX('Equipo y roles'!$E$13:$E$16,P22)) -> A: Isabel Flores Huamaní M: Oriol Romero Saavedra D: Leomar Bonzano Chavez | P22: 2 | Q22: Confirmado | R22: [Fila 19 del original]
A23: =IF(H23="","",COUNTIF($H$11:H23,"?*")) -> 11 | B23: 1.ª visita | C23: 46323 | D23: =IF(C23="","",CHOOSE(WEEKDAY(C23,2),"Lunes","Martes","Miércoles","Jueves","Viernes","Sábado","Domingo")) -> Miércoles | E23: 0.47222222 | F23: 0.54166667 | G23: =IF(AND(E23<>"",F23<>""),F23-E23,"") -> 0.069444444 | H23: PS.05 | I23: Gestión de Recursos Humanos | J23: Jefatura de la Unidad de Personal | K23: Alejandrina Haydee Nario Maguiña | L23: Aula 7D (4.° piso) | M23: Presencial | N23: Google Meet | O23: =IF(P23="","","A: "&INDEX('Equipo y roles'!$C$13:$C$16,P23)&CHAR(10)&"M: "&INDEX('Equipo y roles'!$D$13:$D$16,P23)&CHAR(10)&"D: "&INDEX('Equipo y roles'!$E$13:$E$16,P23)) -> A: Isabel Flores Huamaní M: Oriol Romero Saavedra D: Leomar Bonzano Chavez | P23: 2 | Q23: Confirmado | R23: [Fila 20 del original]
A24: =IF(H24="","",COUNTIF($H$11:H24,"?*")) -> 12 | B24: 1.ª visita | C24: 46323 | D24: =IF(C24="","",CHOOSE(WEEKDAY(C24,2),"Lunes","Martes","Miércoles","Jueves","Viernes","Sábado","Domingo")) -> Miércoles | E24: 0.60416667 | F24: 0.65625 | G24: =IF(AND(E24<>"",F24<>""),F24-E24,"") -> 0.052083333 | H24: PS.06 | I24: Gestión de Abastecimiento y Servicios | J24: Jefatura de la Unidad de Servicios Generales, Operaciones y Mantenimiento | K24: Jesús Gregorio Huamani Gaspar | L24: Aula 7D (4.° piso) | M24: Presencial | N24: Google Meet | O24: =IF(P24="","","A: "&INDEX('Equipo y roles'!$C$13:$C$16,P24)&CHAR(10)&"M: "&INDEX('Equipo y roles'!$D$13:$D$16,P24)&CHAR(10)&"D: "&INDEX('Equipo y roles'!$E$13:$E$16,P24)) -> A: Isabel Flores Huamaní M: Oriol Romero Saavedra D: Leomar Bonzano Chavez | P24: 2 | Q24: Confirmado | R24: [Fila 21 del original]
A25: =IF(H25="","",COUNTIF($H$11:H25,"?*")) -> 13 | B25: 1.ª visita | C25: 46324 | D25: =IF(C25="","",CHOOSE(WEEKDAY(C25,2),"Lunes","Martes","Miércoles","Jueves","Viernes","Sábado","Domingo")) -> Jueves | E25: 0.39583333 | F25: 0.46527778 | G25: =IF(AND(E25<>"",F25<>""),F25-E25,"") -> 0.069444444 | H25: PS.07 | I25: Gestión de Tecnología de la Información | J25: Área de Estadística e Informática | K25: Marcelo Alberto La Rosa Romero Peter Guillermo Agreda Huamán | L25: Sala de Alfombrado | M25: Presencial | N25: Google Meet | O25: =IF(P25="","","A: "&INDEX('Equipo y roles'!$C$13:$C$16,P25)&CHAR(10)&"M: "&INDEX('Equipo y roles'!$D$13:$D$16,P25)&CHAR(10)&"D: "&INDEX('Equipo y roles'!$E$13:$E$16,P25)) -> A: Isabel Flores Huamaní M: Oriol Romero Saavedra D: Leomar Bonzano Chavez | P25: 2 | Q25: Confirmado | R25: Asisten dos integrantes del área. [Fila 22–23 del original]
A26: =IF(H26="","",COUNTIF($H$11:H26,"?*")) -> 14 | B26: 1.ª visita | C26: 46324 | D26: =IF(C26="","",CHOOSE(WEEKDAY(C26,2),"Lunes","Martes","Miércoles","Jueves","Viernes","Sábado","Domingo")) -> Jueves | E26: 0.47222222 | F26: 0.54166667 | G26: =IF(AND(E26<>"",F26<>""),F26-E26,"") -> 0.069444444 | H26: PS.08 | I26: Gestión de Recursos Bibliográficos | J26: Jefatura de la Unidad de Biblioteca, Hemeroteca y Centro de Documentación | K26: David Chavez La Serna | L26: Sala de Alfombrado | M26: Presencial | N26: Google Meet | O26: =IF(P26="","","A: "&INDEX('Equipo y roles'!$C$13:$C$16,P26)&CHAR(10)&"M: "&INDEX('Equipo y roles'!$D$13:$D$16,P26)&CHAR(10)&"D: "&INDEX('Equipo y roles'!$E$13:$E$16,P26)) -> A: Isabel Flores Huamaní M: Oriol Romero Saavedra D: Leomar Bonzano Chavez | P26: 2 | Q26: Confirmado | R26: [Fila 24 del original]
A27: =IF(H27="","",COUNTIF($H$11:H27,"?*")) | B27: Equipo | C27: 46325 | D27: =IF(C27="","",CHOOSE(WEEKDAY(C27,2),"Lunes","Martes","Miércoles","Jueves","Viernes","Sábado","Domingo")) -> Viernes | I27: Reunión de coordinación del equipo · no se levantan diagramaciones | L27: OGPL | R27: Reunión programada con el equipo en la OGPL. Ese día no se levantan diagramaciones. [Fila 25 del original]
A28: NOVIEMBRE 2026
A29: =IF(H29="","",COUNTIF($H$11:H29,"?*")) -> 15 | B29: 1.ª visita | C29: 46328 | D29: =IF(C29="","",CHOOSE(WEEKDAY(C29,2),"Lunes","Martes","Miércoles","Jueves","Viernes","Sábado","Domingo")) -> Lunes | E29: 0.39583333 | F29: 0.46527778 | G29: =IF(AND(E29<>"",F29<>""),F29-E29,"") -> 0.069444444 | H29: PS.10 | I29: Gestión de la Comunicación | J29: Oficina de Imagen de la FPSIC (encargatura) | K29: Cristofer Renato Reyes Bruno | L29: Sala de Alfombrado | M29: Presencial | N29: Google Meet | O29: =IF(P29="","","A: "&INDEX('Equipo y roles'!$C$13:$C$16,P29)&CHAR(10)&"M: "&INDEX('Equipo y roles'!$D$13:$D$16,P29)&CHAR(10)&"D: "&INDEX('Equipo y roles'!$E$13:$E$16,P29)) -> A: Isabel Flores Huamaní M: Oriol Romero Saavedra D: Leomar Bonzano Chavez | P29: 3 | Q29: Confirmado | R29: Primera sesión de PS.10. Alvaro Rojas no asiste por reunión de coordinación. [Fila 27 del original]
A30: =IF(H30="","",COUNTIF($H$11:H30,"?*")) -> 16 | B30: 2.ª visita | C30: 46329 | D30: =IF(C30="","",CHOOSE(WEEKDAY(C30,2),"Lunes","Martes","Miércoles","Jueves","Viernes","Sábado","Domingo")) -> Martes | E30: 0.39583333 | F30: 0.46527778 | G30: =IF(AND(E30<>"",F30<>""),F30-E30,"") -> 0.069444444 | H30: PE.01 | I30: Gestión Estratégica | J30: Jefatura de la Unidad de Planificación, Presupuesto y Racionalización (UPPR) | K30: Rosa Guillermina Coaila Moreno | L30: Aula 7D (4.° piso) | M30: Presencial | N30: Google Meet | O30: =IF(P30="","","A: "&INDEX('Equipo y roles'!$C$13:$C$16,P30)&CHAR(10)&"M: "&INDEX('Equipo y roles'!$D$13:$D$16,P30)&CHAR(10)&"D: "&INDEX('Equipo y roles'!$E$13:$E$16,P30)) -> A: Isabel Flores Huamaní M: Oriol Romero Saavedra D: Leomar Bonzano Chavez | P30: 3 | Q30: Confirmado | R30: [Fila 28 del original]
A31: =IF(H31="","",COUNTIF($H$11:H31,"?*")) -> 17 | B31: 2.ª visita | C31: 46329 | D31: =IF(C31="","",CHOOSE(WEEKDAY(C31,2),"Lunes","Martes","Miércoles","Jueves","Viernes","Sábado","Domingo")) -> Martes | E31: 0.47222222 | F31: 0.54166667 | G31: =IF(AND(E31<>"",F31<>""),F31-E31,"") -> 0.069444444 | H31: PE.02 | I31: Gestión de la Calidad y Mejora Continua | J31: Jefatura de la Oficina de Calidad Académica y Acreditación | K31: Susana Consuelo Roggero Rebaza | L31: Aula 7D (4.° piso) | M31: Presencial | N31: Google Meet | O31: =IF(P31="","","A: "&INDEX('Equipo y roles'!$C$13:$C$16,P31)&CHAR(10)&"M: "&INDEX('Equipo y roles'!$D$13:$D$16,P31)&CHAR(10)&"D: "&INDEX('Equipo y roles'!$E$13:$E$16,P31)) -> A: Isabel Flores Huamaní M: Oriol Romero Saavedra D: Leomar Bonzano Chavez | P31: 3 | Q31: Confirmado | R31: [Fila 29 del original]
A32: =IF(H32="","",COUNTIF($H$11:H32,"?*")) -> 18 | B32: 2.ª visita | C32: 46329 | D32: =IF(C32="","",CHOOSE(WEEKDAY(C32,2),"Lunes","Martes","Miércoles","Jueves","Viernes","Sábado","Domingo")) -> Martes | E32: 0.60416667 | F32: 0.67361111 | G32: =IF(AND(E32<>"",F32<>""),F32-E32,"") -> 0.069444444 | H32: PE.03 | I32: Gestión de Relaciones Interinstitucionales | J32: Dirección de la Escuela Profesional de Psicología Dirección de la Escuela Profesional de Psicología Organizacional y de la Gestión Humana Jefatura de la Unidad de Prácticas Preprofesionales | K32: Carmen Leni Alvarez Taco Abel Cuzcano Zapata Jorge Luis Soto Mateo | L32: Aula 7D (4.° piso) | M32: Presencial | N32: Google Meet | O32: =IF(P32="","","A: "&INDEX('Equipo y roles'!$C$13:$C$16,P32)&CHAR(10)&"M: "&INDEX('Equipo y roles'!$D$13:$D$16,P32)&CHAR(10)&"D: "&INDEX('Equipo y roles'!$E$13:$E$16,P32)) -> A: Isabel Flores Huamaní M: Oriol Romero Saavedra D: Leomar Bonzano Chavez | P32: 3 | Q32: Confirmado | R32: Sesión conjunta. Abel Cuzcano hasta las 16:10; Carmen Alvarez y Jorge Soto hasta las 15:45 (como en el original). [Fila 30–32 del original]
A33: =IF(H33="","",COUNTIF($H$11:H33,"?*")) -> 19 | B33: 2.ª visita | C33: 46330 | D33: =IF(C33="","",CHOOSE(WEEKDAY(C33,2),"Lunes","Martes","Miércoles","Jueves","Viernes","Sábado","Domingo")) -> Miércoles | E33: 0.39583333 | F33: 0.46527778 | G33: =IF(AND(E33<>"",F33<>""),F33-E33,"") -> 0.069444444 | H33: PM.01 | I33: Gestión de la Formación Académica | J33: Vicedecanato Académico de Pregrado | K33: Elisa Beatriz Yanac Reynoso | L33: Sala de Alfombrado | M33: Presencial | N33: Google Meet | O33: =IF(P33="","","A: "&INDEX('Equipo y roles'!$C$13:$C$16,P33)&CHAR(10)&"M: "&INDEX('Equipo y roles'!$D$13:$D$16,P33)&CHAR(10)&"D: "&INDEX('Equipo y roles'!$E$13:$E$16,P33)) -> A: Isabel Flores Huamaní M: Oriol Romero Saavedra D: Leomar Bonzano Chavez | P33: 3 | Q33: Confirmado | R33: [Fila 33 del original]
A34: =IF(H34="","",COUNTIF($H$11:H34,"?*")) -> 20 | B34: 2.ª visita | C34: 46330 | D34: =IF(C34="","",CHOOSE(WEEKDAY(C34,2),"Lunes","Martes","Miércoles","Jueves","Viernes","Sábado","Domingo")) -> Miércoles | E34: 0.47222222 | F34: 0.54166667 | G34: =IF(AND(E34<>"",F34<>""),F34-E34,"") -> 0.069444444 | H34: PM.02 | I34: Gestión de la Investigación | J34: Vicedecanato de Investigación y Posgrado | K34: Carlos Alberto Arenas Iparraguirre | L34: Sala de Alfombrado | M34: Presencial | N34: Google Meet | O34: =IF(P34="","","A: "&INDEX('Equipo y roles'!$C$13:$C$16,P34)&CHAR(10)&"M: "&INDEX('Equipo y roles'!$D$13:$D$16,P34)&CHAR(10)&"D: "&INDEX('Equipo y roles'!$E$13:$E$16,P34)) -> A: Isabel Flores Huamaní M: Oriol Romero Saavedra D: Leomar Bonzano Chavez | P34: 3 | Q34: Confirmado | R34: [Fila 34 del original]
A35: =IF(H35="","",COUNTIF($H$11:H35,"?*")) -> 21 | B35: 2.ª visita | C35: 46330 | D35: =IF(C35="","",CHOOSE(WEEKDAY(C35,2),"Lunes","Martes","Miércoles","Jueves","Viernes","Sábado","Domingo")) -> Miércoles | E35: 0.60416667 | F35: 0.65625 | G35: =IF(AND(E35<>"",F35<>""),F35-E35,"") -> 0.052083333 | H35: PM.03 | I35: Gestión de la Responsabilidad y Vinculación Social | J35: Jefatura del Centro de Responsabilidad Social y Extensión Universitaria | K35: Carmen Magali Meléndez Jara | L35: Sala de Alfombrado | M35: Presencial | N35: Google Meet | O35: =IF(P35="","","A: "&INDEX('Equipo y roles'!$C$13:$C$16,P35)&CHAR(10)&"M: "&INDEX('Equipo y roles'!$D$13:$D$16,P35)&CHAR(10)&"D: "&INDEX('Equipo y roles'!$E$13:$E$16,P35)) -> A: Isabel Flores Huamaní M: Oriol Romero Saavedra D: Leomar Bonzano Chavez | P35: 3 | Q35: Confirmado | R35: [Fila 35 del original]
A36: =IF(H36="","",COUNTIF($H$11:H36,"?*")) -> 22 | B36: 2.ª visita | C36: 46331 | D36: =IF(C36="","",CHOOSE(WEEKDAY(C36,2),"Lunes","Martes","Miércoles","Jueves","Viernes","Sábado","Domingo")) -> Jueves | E36: 0.39583333 | F36: 0.46527778 | G36: =IF(AND(E36<>"",F36<>""),F36-E36,"") -> 0.069444444 | H36: PS.01 | I36: Gestión de Admisión y Matrícula | J36: Vicedecanato Académico de Pregrado | K36: Elisa Beatriz Yanac Reynoso | L36: Sala de Alfombrado | M36: Presencial | N36: Google Meet | O36: =IF(P36="","","A: "&INDEX('Equipo y roles'!$C$13:$C$16,P36)&CHAR(10)&"M: "&INDEX('Equipo y roles'!$D$13:$D$16,P36)&CHAR(10)&"D: "&INDEX('Equipo y roles'!$E$13:$E$16,P36)) -> A: Isabel Flores Huamaní M: Oriol Romero Saavedra D: Leomar Bonzano Chavez | P36: 3 | Q36: Confirmado | R36: [Fila 36 del original]
A37: =IF(H37="","",COUNTIF($H$11:H37,"?*")) -> 23 | B37: 2.ª visita | C37: 46331 | D37: =IF(C37="","",CHOOSE(WEEKDAY(C37,2),"Lunes","Martes","Miércoles","Jueves","Viernes","Sábado","Domingo")) -> Jueves | E37: 0.47222222 | F37: 0.54166667 | G37: =IF(AND(E37<>"",F37<>""),F37-E37,"") -> 0.069444444 | H37: PS.02 | I37: Gestión Documental | J37: Jefatura de la Unidad de Trámite Documentario y Archivo | K37: Edith Maribel Collins García | L37: Sala de Alfombrado | M37: Presencial | N37: Google Meet | O37: =IF(P37="","","A: "&INDEX('Equipo y roles'!$C$13:$C$16,P37)&CHAR(10)&"M: "&INDEX('Equipo y roles'!$D$13:$D$16,P37)&CHAR(10)&"D: "&INDEX('Equipo y roles'!$E$13:$E$16,P37)) -> A: Isabel Flores Huamaní M: Oriol Romero Saavedra D: Leomar Bonzano Chavez | P37: 3 | Q37: Confirmado | R37: [Fila 37 del original]
A38: =IF(H38="","",COUNTIF($H$11:H38,"?*")) -> 24 | B38: 2.ª visita | C38: 46331 | D38: =IF(C38="","",CHOOSE(WEEKDAY(C38,2),"Lunes","Martes","Miércoles","Jueves","Viernes","Sábado","Domingo")) -> Jueves | E38: 0.60416667 | F38: 0.65625 | G38: =IF(AND(E38<>"",F38<>""),F38-E38,"") -> 0.052083333 | H38: PS.03 | I38: Gestión de Bienestar Integral | J38: Jefatura de la Unidad de Bienestar | K38: Rosa Digna Luna Pérez | L38: Sala de Alfombrado | M38: Presencial | N38: Google Meet | O38: =IF(P38="","","A: "&INDEX('Equipo y roles'!$C$13:$C$16,P38)&CHAR(10)&"M: "&INDEX('Equipo y roles'!$D$13:$D$16,P38)&CHAR(10)&"D: "&INDEX('Equipo y roles'!$E$13:$E$16,P38)) -> A: Isabel Flores Huamaní M: Oriol Romero Saavedra D: Leomar Bonzano Chavez | P38: 3 | Q38: Confirmado | R38: [Fila 38 del original]
A39: =IF(H39="","",COUNTIF($H$11:H39,"?*")) | B39: Equipo | C39: 46332 | D39: =IF(C39="","",CHOOSE(WEEKDAY(C39,2),"Lunes","Martes","Miércoles","Jueves","Viernes","Sábado","Domingo")) -> Viernes | I39: Reunión de coordinación del equipo · no se levantan diagramaciones | L39: OGPL | R39: Reunión programada con el equipo en la OGPL. Ese día no se levantan diagramaciones. [Fila 39 del original]
A40: =IF(H40="","",COUNTIF($H$11:H40,"?*")) -> 25 | B40: 2.ª visita | C40: 46335 | D40: =IF(C40="","",CHOOSE(WEEKDAY(C40,2),"Lunes","Martes","Miércoles","Jueves","Viernes","Sábado","Domingo")) -> Lunes | E40: 0.39583333 | F40: 0.46527778 | G40: =IF(AND(E40<>"",F40<>""),F40-E40,"") -> 0.069444444 | H40: PS.04 | I40: Gestión de Recursos Económicos | J40: Jefatura de la Unidad de Economía | K40: Nestor Felipe Chalque Alvarez | L40: Sala de Alfombrado | M40: Presencial | N40: Google Meet | O40: =IF(P40="","","A: "&INDEX('Equipo y roles'!$C$13:$C$16,P40)&CHAR(10)&"M: "&INDEX('Equipo y roles'!$D$13:$D$16,P40)&CHAR(10)&"D: "&INDEX('Equipo y roles'!$E$13:$E$16,P40)) -> A: Isabel Flores Huamaní M: Oriol Romero Saavedra D: Leomar Bonzano Chavez | P40: 4 | Q40: Confirmado | R40: [Fila 40 del original]
A41: =IF(H41="","",COUNTIF($H$11:H41,"?*")) -> 26 | B41: 2.ª visita | C41: 46335 | D41: =IF(C41="","",CHOOSE(WEEKDAY(C41,2),"Lunes","Martes","Miércoles","Jueves","Viernes","Sábado","Domingo")) -> Lunes | E41: 0.47222222 | F41: 0.54166667 | G41: =IF(AND(E41<>"",F41<>""),F41-E41,"") -> 0.069444444 | H41: PS.05 | I41: Gestión de Recursos Humanos | J41: Jefatura de la Unidad de Personal | K41: Alejandrina Haydee Nario Maguiña | L41: Sala de Alfombrado | M41: Presencial | N41: Google Meet | O41: =IF(P41="","","A: "&INDEX('Equipo y roles'!$C$13:$C$16,P41)&CHAR(10)&"M: "&INDEX('Equipo y roles'!$D$13:$D$16,P41)&CHAR(10)&"D: "&INDEX('Equipo y roles'!$E$13:$E$16,P41)) -> A: Isabel Flores Huamaní M: Oriol Romero Saavedra D: Leomar Bonzano Chavez | P41: 4 | Q41: Confirmado | R41: [Fila 41 del original]
A42: =IF(H42="","",COUNTIF($H$11:H42,"?*")) -> 27 | B42: 2.ª visita | C42: 46335 | D42: =IF(C42="","",CHOOSE(WEEKDAY(C42,2),"Lunes","Martes","Miércoles","Jueves","Viernes","Sábado","Domingo")) -> Lunes | E42: 0.60416667 | F42: 0.65625 | G42: =IF(AND(E42<>"",F42<>""),F42-E42,"") -> 0.052083333 | H42: PS.06 | I42: Gestión de Abastecimiento y Servicios | J42: Jefatura de la Unidad de Servicios Generales, Operaciones y Mantenimiento | K42: Jesús Gregorio Huamani Gaspar | L42: Sala de Alfombrado | M42: Presencial | N42: Google Meet | O42: =IF(P42="","","A: "&INDEX('Equipo y roles'!$C$13:$C$16,P42)&CHAR(10)&"M: "&INDEX('Equipo y roles'!$D$13:$D$16,P42)&CHAR(10)&"D: "&INDEX('Equipo y roles'!$E$13:$E$16,P42)) -> A: Isabel Flores Huamaní M: Oriol Romero Saavedra D: Leomar Bonzano Chavez | P42: 4 | Q42: Confirmado | R42: [Fila 42 del original]
A43: =IF(H43="","",COUNTIF($H$11:H43,"?*")) -> 28 | B43: 2.ª visita | C43: 46336 | D43: =IF(C43="","",CHOOSE(WEEKDAY(C43,2),"Lunes","Martes","Miércoles","Jueves","Viernes","Sábado","Domingo")) -> Martes | E43: 0.39583333 | F43: 0.46527778 | G43: =IF(AND(E43<>"",F43<>""),F43-E43,"") -> 0.069444444 | H43: PS.07 | I43: Gestión de Tecnología de la Información | J43: Área de Estadística e Informática | K43: Marcelo Alberto La Rosa Romero Peter Guillermo Agreda Huamán | L43: Sala de Alfombrado | M43: Presencial | N43: Google Meet | O43: =IF(P43="","","A: "&INDEX('Equipo y roles'!$C$13:$C$16,P43)&CHAR(10)&"M: "&INDEX('Equipo y roles'!$D$13:$D$16,P43)&CHAR(10)&"D: "&INDEX('Equipo y roles'!$E$13:$E$16,P43)) -> A: Isabel Flores Huamaní M: Oriol Romero Saavedra D: Leomar Bonzano Chavez | P43: 4 | Q43: Confirmado | R43: Asisten dos integrantes del área. El original decía «Martes Lunes»: el 10/11/2026 es martes. [Fila 43–44 del original]
...

Sheet Calendario
A1: CALENDARIO DE VISITAS POR PROCESO
A2: Días hábiles del 20/10 al 11/11/2026 · 1.ª y 2.ª visita de cada proceso
A3: Universidad Nacional Mayor de San Marcos · Oficina General de Planificación · Oficina de Racionalización | Proyecto P01 · Plan P01-PG-F2 v1.1 | Versión 2.0 del cronograma · revisada el 15/10/2026
A5: Leyenda: 1.ª = primera visita de levantamiento · 2.ª = segunda visita · Equipo = reunión de coordinación del equipo (sin levantamiento) · Apert. = reunión de apertura
A6: Código | B6: Proceso | C6: Unidad orgánica | D6: 46315 | E6: 46316 | F6: 46317 | G6: 46318 | H6: 46321 | I6: 46322 | J6: 46323 | K6: 46324 | L6: 46325 | M6: 46328 | N6: 46329 | O6: 46330 | P6: 46331 | Q6: 46332 | R6: 46335 | S6: 46336 | T6: 46337 | U6: Sesiones
D7: =LEFT(CHOOSE(WEEKDAY(D$6,2),"Lunes","Martes","Miércoles","Jueves","Viernes","Sábado","Domingo"),3) -> Mar | E7: =LEFT(CHOOSE(WEEKDAY(E$6,2),"Lunes","Martes","Miércoles","Jueves","Viernes","Sábado","Domingo"),3) -> Mié | F7: =LEFT(CHOOSE(WEEKDAY(F$6,2),"Lunes","Martes","Miércoles","Jueves","Viernes","Sábado","Domingo"),3) -> Jue | G7: =LEFT(CHOOSE(WEEKDAY(G$6,2),"Lunes","Martes","Miércoles","Jueves","Viernes","Sábado","Domingo"),3) -> Vie | H7: =LEFT(CHOOSE(WEEKDAY(H$6,2),"Lunes","Martes","Miércoles","Jueves","Viernes","Sábado","Domingo"),3) -> Lun | I7: =LEFT(CHOOSE(WEEKDAY(I$6,2),"Lunes","Martes","Miércoles","Jueves","Viernes","Sábado","Domingo"),3) -> Mar | J7: =LEFT(CHOOSE(WEEKDAY(J$6,2),"Lunes","Martes","Miércoles","Jueves","Viernes","Sábado","Domingo"),3) -> Mié | K7: =LEFT(CHOOSE(WEEKDAY(K$6,2),"Lunes","Martes","Miércoles","Jueves","Viernes","Sábado","Domingo"),3) -> Jue | ... T7: =LEFT(CHOOSE(WEEKDAY(T$6,2),"Lunes","Martes","Miércoles","Jueves","Viernes","Sábado","Domingo"),3) -> Mié
D8: =IF(D$6=DATE(2026,10,20),"Apert.",IF(COUNTIFS(Cronograma!$C$11:$C$45,D$6,Cronograma!$B$11:$B$45,"Equipo")>0,"Equipo","")) -> Apert. | E8: =IF(E$6=DATE(2026,10,20),"Apert.",IF(COUNTIFS(Cronograma!$C$11:$C$45,E$6,Cronograma!$B$11:$B$45,"Equipo")>0,"Equipo","")) | F8: =IF(F$6=DATE(2026,10,20),"Apert.",IF(COUNTIFS(Cronograma!$C$11:$C$45,F$6,Cronograma!$B$11:$B$45,"Equipo")>0,"Equipo","")) | G8: =IF(G$6=DATE(2026,10,20),"Apert.",IF(COUNTIFS(Cronograma!$C$11:$C$45,G$6,Cronograma!$B$11:$B$45,"Equipo")>0,"Equipo","")) | H8: =IF(H$6=DATE(2026,10,20),"Apert.",IF(COUNTIFS(Cronograma!$C$11:$C$45,H$6,Cronograma!$B$11:$B$45,"Equipo")>0,"Equipo","")) -> Equipo | I8: =IF(I$6=DATE(2026,10,20),"Apert.",IF(COUNTIFS(Cronograma!$C$11:$C$45,I$6,Cronograma!$B$11:$B$45,"Equipo")>0,"Equipo","")) | J8: =IF(J$6=DATE(2026,10,20),"Apert.",IF(COUNTIFS(Cronograma!$C$11:$C$45,J$6,Cronograma!$B$11:$B$45,"Equipo")>0,"Equipo","")) | K8: =IF(K$6=DATE(2026,10,20),"Apert.",IF(COUNTIFS(Cronograma!$C$11:$C$45,K$6,Cronograma!$B$11:$B$45,"Equipo")>0,"Equipo","")) | ... T8: =IF(T$6=DATE(2026,10,20),"Apert.",IF(COUNTIFS(Cronograma!$C$11:$C$45,T$6,Cronograma!$B$11:$B$45,"Equipo")>0,"Equipo",""))
A9: PE.01 | B9: Gestión Estratégica | C9: Jefatura de la Unidad de Planificación, Presupuesto y Racionalización (UPPR) | D9: =IF(COUNTIFS(Cronograma!$H$11:$H$45,$A9,Cronograma!$C$11:$C$45,D$6)=0,"",IF(COUNTIFS(Cronograma!$H$11:$H$45,$A9,Cronograma!$C$11:$C$45,D$6,Cronograma!$B$11:$B$45,"1.ª visita")>0,"1.ª","2.ª")) | E9: =IF(COUNTIFS(Cronograma!$H$11:$H$45,$A9,Cronograma!$C$11:$C$45,E$6)=0,"",IF(COUNTIFS(Cronograma!$H$11:$H$45,$A9,Cronograma!$C$11:$C$45,E$6,Cronograma!$B$11:$B$45,"1.ª visita")>0,"1.ª","2.ª")) -> 1.ª | F9: =IF(COUNTIFS(Cronograma!$H$11:$H$45,$A9,Cronograma!$C$11:$C$45,F$6)=0,"",IF(COUNTIFS(Cronograma!$H$11:$H$45,$A9,Cronograma!$C$11:$C$45,F$6,Cronograma!$B$11:$B$45,"1.ª visita")>0,"1.ª","2.ª")) | G9: =IF(COUNTIFS(Cronograma!$H$11:$H$45,$A9,Cronograma!$C$11:$C$45,G$6)=0,"",IF(COUNTIFS(Cronograma!$H$11:$H$45,$A9,Cronograma!$C$11:$C$45,G$6,Cronograma!$B$11:$B$45,"1.ª visita")>0,"1.ª","2.ª")) | H9: =IF(COUNTIFS(Cronograma!$H$11:$H$45,$A9,Cronograma!$C$11:$C$45,H$6)=0,"",IF(COUNTIFS(Cronograma!$H$11:$H$45,$A9,Cronograma!$C$11:$C$45,H$6,Cronograma!$B$11:$B$45,"1.ª visita")>0,"1.ª","2.ª")) | I9: =IF(COUNTIFS(Cronograma!$H$11:$H$45,$A9,Cronograma!$C$11:$C$45,I$6)=0,"",IF(COUNTIFS(Cronograma!$H$11:$H$45,$A9,Cronograma!$C$11:$C$45,I$6,Cronograma!$B$11:$B$45,"1.ª visita")>0,"1.ª","2.ª")) | J9: =IF(COUNTIFS(Cronograma!$H$11:$H$45,$A9,Cronograma!$C$11:$C$45,J$6)=0,"",IF(COUNTIFS(Cronograma!$H$11:$H$45,$A9,Cronograma!$C$11:$C$45,J$6,Cronograma!$B$11:$B$45,"1.ª visita")>0,"1.ª","2.ª")) | K9: =IF(COUNTIFS(Cronograma!$H$11:$H$45,$A9,Cronograma!$C$11:$C$45,K$6)=0,"",IF(COUNTIFS(Cronograma!$H$11:$H$45,$A9,Cronograma!$C$11:$C$45,K$6,Cronograma!$B$11:$B$45,"1.ª visita")>0,"1.ª","2.ª")) | ... T9: =IF(COUNTIFS(Cronograma!$H$11:$H$45,$A9,Cronograma!$C$11:$C$45,T$6)=0,"",IF(COUNTIFS(Cronograma!$H$11:$H$45,$A9,Cronograma!$C$11:$C$45,T$6,Cronograma!$B$11:$B$45,"1.ª visita")>0,"1.ª","2.ª")) | U9: =COUNTIF(Cronograma!$H$11:$H$45,$A9) -> 2
A10: PE.02 | B10: Gestión de la Calidad y Mejora Continua | C10: Jefatura de la Oficina de Calidad Académica y Acreditación | D10: =IF(COUNTIFS(Cronograma!$H$11:$H$45,$A10,Cronograma!$C$11:$C$45,D$6)=0,"",IF(COUNTIFS(Cronograma!$H$11:$H$45,$A10,Cronograma!$C$11:$C$45,D$6,Cronograma!$B$11:$B$45,"1.ª visita")>0,"1.ª","2.ª")) | E10: =IF(COUNTIFS(Cronograma!$H$11:$H$45,$A10,Cronograma!$C$11:$C$45,E$6)=0,"",IF(COUNTIFS(Cronograma!$H$11:$H$45,$A10,Cronograma!$C$11:$C$45,E$6,Cronograma!$B$11:$B$45,"1.ª visita")>0,"1.ª","2.ª")) -> 1.ª | F10: =IF(COUNTIFS(Cronograma!$H$11:$H$45,$A10,Cronograma!$C$11:$C$45,F$6)=0,"",IF(COUNTIFS(Cronograma!$H$11:$H$45,$A10,Cronograma!$C$11:$C$45,F$6,Cronograma!$B$11:$B$45,"1.ª visita")>0,"1.ª","2.ª")) | G10: =IF(COUNTIFS(Cronograma!$H$11:$H$45,$A10,Cronograma!$C$11:$C$45,G$6)=0,"",IF(COUNTIFS(Cronograma!$H$11:$H$45,$A10,Cronograma!$C$11:$C$45,G$6,Cronograma!$B$11:$B$45,"1.ª visita")>0,"1.ª","2.ª")) | H10: =IF(COUNTIFS(Cronograma!$H$11:$H$45,$A10,Cronograma!$C$11:$C$45,H$6)=0,"",IF(COUNTIFS(Cronograma!$H$11:$H$45,$A10,Cronograma!$C$11:$C$45,H$6,Cronograma!$B$11:$B$45,"1.ª visita")>0,"1.ª","2.ª")) | I10: =IF(COUNTIFS(Cronograma!$H$11:$H$45,$A10,Cronograma!$C$11:$C$45,I$6)=0,"",IF(COUNTIFS(Cronograma!$H$11:$H$45,$A10,Cronograma!$C$11:$C$45,I$6,Cronograma!$B$11:$B$45,"1.ª visita")>0,"1.ª","2.ª")) | J10: =IF(COUNTIFS(Cronograma!$H$11:$H$45,$A10,Cronograma!$C$11:$C$45,J$6)=0,"",IF(COUNTIFS(Cronograma!$H$11:$H$45,$A10,Cronograma!$C$11:$C$45,J$6,Cronograma!$B$11:$B$45,"1.ª visita")>0,"1.ª","2.ª")) | K10: =IF(COUNTIFS(Cronograma!$H$11:$H$45,$A10,Cronograma!$C$11:$C$45,K$6)=0,"",IF(COUNTIFS(Cronograma!$H$11:$H$45,$A10,Cronograma!$C$11:$C$45,K$6,Cronograma!$B$11:$B$45,"1.ª visita")>0,"1.ª","2.ª")) | ... T10: =IF(COUNTIFS(Cronograma!$H$11:$H$45,$A10,Cronograma!$C$11:$C$45,T$6)=0,"",IF(COUNTIFS(Cronograma!$H$11:$H$45,$A10,Cronograma!$C$11:$C$45,T$6,Cronograma!$B$11:$B$45,"1.ª visita")>0,"1.ª","2.ª")) | U10: =COUNTIF(Cronograma!$H$11:$H$45,$A10) -> 2
A11: PE.03 | B11: Gestión de Relaciones Interinstitucionales | C11: Dirección de la Escuela Profesional de Psicología Dirección de la Escuela Profesional de Psicología Organizacional y de la Gestión Humana Jefatura de la Unidad de Prácticas Preprofesionales | D11: =IF(COUNTIFS(Cronograma!$H$11:$H$45,$A11,Cronograma!$C$11:$C$45,D$6)=0,"",IF(COUNTIFS(Cronograma!$H$11:$H$45,$A11,Cronograma!$C$11:$C$45,D$6,Cronograma!$B$11:$B$45,"1.ª visita")>0,"1.ª","2.ª")) | E11: =IF(COUNTIFS(Cronograma!$H$11:$H$45,$A11,Cronograma!$C$11:$C$45,E$6)=0,"",IF(COUNTIFS(Cronograma!$H$11:$H$45,$A11,Cronograma!$C$11:$C$45,E$6,Cronograma!$B$11:$B$45,"1.ª visita")>0,"1.ª","2.ª")) -> 1.ª | F11: =IF(COUNTIFS(Cronograma!$H$11:$H$45,$A11,Cronograma!$C$11:$C$45,F$6)=0,"",IF(COUNTIFS(Cronograma!$H$11:$H$45,$A11,Cronograma!$C$11:$C$45,F$6,Cronograma!$B$11:$B$45,"1.ª visita")>0,"1.ª","2.ª")) | G11: =IF(COUNTIFS(Cronograma!$H$11:$H$45,$A11,Cronograma!$C$11:$C$45,G$6)=0,"",IF(COUNTIFS(Cronograma!$H$11:$H$45,$A11,Cronograma!$C$11:$C$45,G$6,Cronograma!$B$11:$B$45,"1.ª visita")>0,"1.ª","2.ª")) | H11: =IF(COUNTIFS(Cronograma!$H$11:$H$45,$A11,Cronograma!$C$11:$C$45,H$6)=0,"",IF(COUNTIFS(Cronograma!$H$11:$H$45,$A11,Cronograma!$C$11:$C$45,H$6,Cronograma!$B$11:$B$45,"1.ª visita")>0,"1.ª","2.ª")) | I11: =IF(COUNTIFS(Cronograma!$H$11:$H$45,$A11,Cronograma!$C$11:$C$45,I$6)=0,"",IF(COUNTIFS(Cronograma!$H$11:$H$45,$A11,Cronograma!$C$11:$C$45,I$6,Cronograma!$B$11:$B$45,"1.ª visita")>0,"1.ª","2.ª")) | J11: =IF(COUNTIFS(Cronograma!$H$11:$H$45,$A11,Cronograma!$C$11:$C$45,J$6)=0,"",IF(COUNTIFS(Cronograma!$H$11:$H$45,$A11,Cronograma!$C$11:$C$45,J$6,Cronograma!$B$11:$B$45,"1.ª visita")>0,"1.ª","2.ª")) | K11: =IF(COUNTIFS(Cronograma!$H$11:$H$45,$A11,Cronograma!$C$11:$C$45,K$6)=0,"",IF(COUNTIFS(Cronograma!$H$11:$H$45,$A11,Cronograma!$C$11:$C$45,K$6,Cronograma!$B$11:$B$45,"1.ª visita")>0,"1.ª","2.ª")) | ... T11: =IF(COUNTIFS(Cronograma!$H$11:$H$45,$A11,Cronograma!$C$11:$C$45,T$6)=0,"",IF(COUNTIFS(Cronograma!$H$11:$H$45,$A11,Cronograma!$C$11:$C$45,T$6,Cronograma!$B$11:$B$45,"1.ª visita")>0,"1.ª","2.ª")) | U11: =COUNTIF(Cronograma!$H$11:$H$45,$A11) -> 2
A12: PM.01 | B12: Gestión de la Formación Académica | C12: Vicedecanato Académico de Pregrado | D12: =IF(COUNTIFS(Cronograma!$H$11:$H$45,$A12,Cronograma!$C$11:$C$45,D$6)=0,"",IF(COUNTIFS(Cronograma!$H$11:$H$45,$A12,Cronograma!$C$11:$C$45,D$6,Cronograma!$B$11:$B$45,"1.ª visita")>0,"1.ª","2.ª")) | E12: =IF(COUNTIFS(Cronograma!$H$11:$H$45,$A12,Cronograma!$C$11:$C$45,E$6)=0,"",IF(COUNTIFS(Cronograma!$H$11:$H$45,$A12,Cronograma!$C$11:$C$45,E$6,Cronograma!$B$11:$B$45,"1.ª visita")>0,"1.ª","2.ª")) | F12: =IF(COUNTIFS(Cronograma!$H$11:$H$45,$A12,Cronograma!$C$11:$C$45,F$6)=0,"",IF(COUNTIFS(Cronograma!$H$11:$H$45,$A12,Cronograma!$C$11:$C$45,F$6,Cronograma!$B$11:$B$45,"1.ª visita")>0,"1.ª","2.ª")) -> 1.ª | G12: =IF(COUNTIFS(Cronograma!$H$11:$H$45,$A12,Cronograma!$C$11:$C$45,G$6)=0,"",IF(COUNTIFS(Cronograma!$H$11:$H$45,$A12,Cronograma!$C$11:$C$45,G$6,Cronograma!$B$11:$B$45,"1.ª visita")>0,"1.ª","2.ª")) | H12: =IF(COUNTIFS(Cronograma!$H$11:$H$45,$A12,Cronograma!$C$11:$C$45,H$6)=0,"",IF(COUNTIFS(Cronograma!$H$11:$H$45,$A12,Cronograma!$C$11:$C$45,H$6,Cronograma!$B$11:$B$45,"1.ª visita")>0,"1.ª","2.ª")) | I12: =IF(COUNTIFS(Cronograma!$H$11:$H$45,$A12,Cronograma!$C$11:$C$45,I$6)=0,"",IF(COUNTIFS(Cronograma!$H$11:$H$45,$A12,Cronograma!$C$11:$C$45,I$6,Cronograma!$B$11:$B$45,"1.ª visita")>0,"1.ª","2.ª")) | J12: =IF(COUNTIFS(Cronograma!$H$11:$H$45,$A12,Cronograma!$C$11:$C$45,J$6)=0,"",IF(COUNTIFS(Cronograma!$H$11:$H$45,$A12,Cronograma!$C$11:$C$45,J$6,Cronograma!$B$11:$B$45,"1.ª visita")>0,"1.ª","2.ª")) | K12: =IF(COUNTIFS(Cronograma!$H$11:$H$45,$A12,Cronograma!$C$11:$C$45,K$6)=0,"",IF(COUNTIFS(Cronograma!$H$11:$H$45,$A12,Cronograma!$C$11:$C$45,K$6,Cronograma!$B$11:$B$45,"1.ª visita")>0,"1.ª","2.ª")) | ... T12: =IF(COUNTIFS(Cronograma!$H$11:$H$45,$A12,Cronograma!$C$11:$C$45,T$6)=0,"",IF(COUNTIFS(Cronograma!$H$11:$H$45,$A12,Cronograma!$C$11:$C$45,T$6,Cronograma!$B$11:$B$45,"1.ª visita")>0,"1.ª","2.ª")) | U12: =COUNTIF(Cronograma!$H$11:$H$45,$A12) -> 2
A13: PM.02 | B13: Gestión de la Investigación | C13: Vicedecanato de Investigación y Posgrado | D13: =IF(COUNTIFS(Cronograma!$H$11:$H$45,$A13,Cronograma!$C$11:$C$45,D$6)=0,"",IF(COUNTIFS(Cronograma!$H$11:$H$45,$A13,Cronograma!$C$11:$C$45,D$6,Cronograma!$B$11:$B$45,"1.ª visita")>0,"1.ª","2.ª")) | E13: =IF(COUNTIFS(Cronograma!$H$11:$H$45,$A13,Cronograma!$C$11:$C$45,E$6)=0,"",IF(COUNTIFS(Cronograma!$H$11:$H$45,$A13,Cronograma!$C$11:$C$45,E$6,Cronograma!$B$11:$B$45,"1.ª visita")>0,"1.ª","2.ª")) | F13: =IF(COUNTIFS(Cronograma!$H$11:$H$45,$A13,Cronograma!$C$11:$C$45,F$6)=0,"",IF(COUNTIFS(Cronograma!$H$11:$H$45,$A13,Cronograma!$C$11:$C$45,F$6,Cronograma!$B$11:$B$45,"1.ª visita")>0,"1.ª","2.ª")) -> 1.ª | G13: =IF(COUNTIFS(Cronograma!$H$11:$H$45,$A13,Cronograma!$C$11:$C$45,G$6)=0,"",IF(COUNTIFS(Cronograma!$H$11:$H$45,$A13,Cronograma!$C$11:$C$45,G$6,Cronograma!$B$11:$B$45,"1.ª visita")>0,"1.ª","2.ª")) | H13: =IF(COUNTIFS(Cronograma!$H$11:$H$45,$A13,Cronograma!$C$11:$C$45,H$6)=0,"",IF(COUNTIFS(Cronograma!$H$11:$H$45,$A13,Cronograma!$C$11:$C$45,H$6,Cronograma!$B$11:$B$45,"1.ª visita")>0,"1.ª","2.ª")) | I13: =IF(COUNTIFS(Cronograma!$H$11:$H$45,$A13,Cronograma!$C$11:$C$45,I$6)=0,"",IF(COUNTIFS(Cronograma!$H$11:$H$45,$A13,Cronograma!$C$11:$C$45,I$6,Cronograma!$B$11:$B$45,"1.ª visita")>0,"1.ª","2.ª")) | J13: =IF(COUNTIFS(Cronograma!$H$11:$H$45,$A13,Cronograma!$C$11:$C$45,J$6)=0,"",IF(COUNTIFS(Cronograma!$H$11:$H$45,$A13,Cronograma!$C$11:$C$45,J$6,Cronograma!$B$11:$B$45,"1.ª visita")>0,"1.ª","2.ª")) | K13: =IF(COUNTIFS(Cronograma!$H$11:$H$45,$A13,Cronograma!$C$11:$C$45,K$6)=0,"",IF(COUNTIFS(Cronograma!$H$11:$H$45,$A13,Cronograma!$C$11:$C$45,K$6,Cronograma!$B$11:$B$45,"1.ª visita")>0,"1.ª","2.ª")) | ... T13: =IF(COUNTIFS(Cronograma!$H$11:$H$45,$A13,Cronograma!$C$11:$C$45,T$6)=0,"",IF(COUNTIFS(Cronograma!$H$11:$H$45,$A13,Cronograma!$C$11:$C$45,T$6,Cronograma!$B$11:$B$45,"1.ª visita")>0,"1.ª","2.ª")) | U13: =COUNTIF(Cronograma!$H$11:$H$45,$A13) -> 2
A14: PM.03 | B14: Gestión de la Responsabilidad y Vinculación Social | C14: Jefatura del Centro de Responsabilidad Social y Extensión Universitaria | D14: =IF(COUNTIFS(Cronograma!$H$11:$H$45,$A14,Cronograma!$C$11:$C$45,D$6)=0,"",IF(COUNTIFS(Cronograma!$H$11:$H$45,$A14,Cronograma!$C$11:$C$45,D$6,Cronograma!$B$11:$B$45,"1.ª visita")>0,"1.ª","2.ª")) | E14: =IF(COUNTIFS(Cronograma!$H$11:$H$45,$A14,Cronograma!$C$11:$C$45,E$6)=0,"",IF(COUNTIFS(Cronograma!$H$11:$H$45,$A14,Cronograma!$C$11:$C$45,E$6,Cronograma!$B$11:$B$45,"1.ª visita")>0,"1.ª","2.ª")) | F14: =IF(COUNTIFS(Cronograma!$H$11:$H$45,$A14,Cronograma!$C$11:$C$45,F$6)=0,"",IF(COUNTIFS(Cronograma!$H$11:$H$45,$A14,Cronograma!$C$11:$C$45,F$6,Cronograma!$B$11:$B$45,"1.ª visita")>0,"1.ª","2.ª")) -> 1.ª | G14: =IF(COUNTIFS(Cronograma!$H$11:$H$45,$A14,Cronograma!$C$11:$C$45,G$6)=0,"",IF(COUNTIFS(Cronograma!$H$11:$H$45,$A14,Cronograma!$C$11:$C$45,G$6,Cronograma!$B$11:$B$45,"1.ª visita")>0,"1.ª","2.ª")) | H14: =IF(COUNTIFS(Cronograma!$H$11:$H$45,$A14,Cronograma!$C$11:$C$45,H$6)=0,"",IF(COUNTIFS(Cronograma!$H$11:$H$45,$A14,Cronograma!$C$11:$C$45,H$6,Cronograma!$B$11:$B$45,"1.ª visita")>0,"1.ª","2.ª")) | I14: =IF(COUNTIFS(Cronograma!$H$11:$H$45,$A14,Cronograma!$C$11:$C$45,I$6)=0,"",IF(COUNTIFS(Cronograma!$H$11:$H$45,$A14,Cronograma!$C$11:$C$45,I$6,Cronograma!$B$11:$B$45,"1.ª visita")>0,"1.ª","2.ª")) | J14: =IF(COUNTIFS(Cronograma!$H$11:$H$45,$A14,Cronograma!$C$11:$C$45,J$6)=0,"",IF(COUNTIFS(Cronograma!$H$11:$H$45,$A14,Cronograma!$C$11:$C$45,J$6,Cronograma!$B$11:$B$45,"1.ª visita")>0,"1.ª","2.ª")) | K14: =IF(COUNTIFS(Cronograma!$H$11:$H$45,$A14,Cronograma!$C$11:$C$45,K$6)=0,"",IF(COUNTIFS(Cronograma!$H$11:$H$45,$A14,Cronograma!$C$11:$C$45,K$6,Cronograma!$B$11:$B$45,"1.ª visita")>0,"1.ª","2.ª")) | ... T14: =IF(COUNTIFS(Cronograma!$H$11:$H$45,$A14,Cronograma!$C$11:$C$45,T$6)=0,"",IF(COUNTIFS(Cronograma!$H$11:$H$45,$A14,Cronograma!$C$11:$C$45,T$6,Cronograma!$B$11:$B$45,"1.ª visita")>0,"1.ª","2.ª")) | U14: =COUNTIF(Cronograma!$H$11:$H$45,$A14) -> 2
A15: PS.01 | B15: Gestión de Admisión y Matrícula | C15: Vicedecanato Académico de Pregrado | D15: =IF(COUNTIFS(Cronograma!$H$11:$H$45,$A15,Cronograma!$C$11:$C$45,D$6)=0,"",IF(COUNTIFS(Cronograma!$H$11:$H$45,$A15,Cronograma!$C$11:$C$45,D$6,Cronograma!$B$11:$B$45,"1.ª visita")>0,"1.ª","2.ª")) | E15: =IF(COUNTIFS(Cronograma!$H$11:$H$45,$A15,Cronograma!$C$11:$C$45,E$6)=0,"",IF(COUNTIFS(Cronograma!$H$11:$H$45,$A15,Cronograma!$C$11:$C$45,E$6,Cronograma!$B$11:$B$45,"1.ª visita")>0,"1.ª","2.ª")) | F15: =IF(COUNTIFS(Cronograma!$H$11:$H$45,$A15,Cronograma!$C$11:$C$45,F$6)=0,"",IF(COUNTIFS(Cronograma!$H$11:$H$45,$A15,Cronograma!$C$11:$C$45,F$6,Cronograma!$B$11:$B$45,"1.ª visita")>0,"1.ª","2.ª")) | G15: =IF(COUNTIFS(Cronograma!$H$11:$H$45,$A15,Cronograma!$C$11:$C$45,G$6)=0,"",IF(COUNTIFS(Cronograma!$H$11:$H$45,$A15,Cronograma!$C$11:$C$45,G$6,Cronograma!$B$11:$B$45,"1.ª visita")>0,"1.ª","2.ª")) | H15: =IF(COUNTIFS(Cronograma!$H$11:$H$45,$A15,Cronograma!$C$11:$C$45,H$6)=0,"",IF(COUNTIFS(Cronograma!$H$11:$H$45,$A15,Cronograma!$C$11:$C$45,H$6,Cronograma!$B$11:$B$45,"1.ª visita")>0,"1.ª","2.ª")) | I15: =IF(COUNTIFS(Cronograma!$H$11:$H$45,$A15,Cronograma!$C$11:$C$45,I$6)=0,"",IF(COUNTIFS(Cronograma!$H$11:$H$45,$A15,Cronograma!$C$11:$C$45,I$6,Cronograma!$B$11:$B$45,"1.ª visita")>0,"1.ª","2.ª")) -> 1.ª | J15: =IF(COUNTIFS(Cronograma!$H$11:$H$45,$A15,Cronograma!$C$11:$C$45,J$6)=0,"",IF(COUNTIFS(Cronograma!$H$11:$H$45,$A15,Cronograma!$C$11:$C$45,J$6,Cronograma!$B$11:$B$45,"1.ª visita")>0,"1.ª","2.ª")) | K15: =IF(COUNTIFS(Cronograma!$H$11:$H$45,$A15,Cronograma!$C$11:$C$45,K$6)=0,"",IF(COUNTIFS(Cronograma!$H$11:$H$45,$A15,Cronograma!$C$11:$C$45,K$6,Cronograma!$B$11:$B$45,"1.ª visita")>0,"1.ª","2.ª")) | ... T15: =IF(COUNTIFS(Cronograma!$H$11:$H$45,$A15,Cronograma!$C$11:$C$45,T$6)=0,"",IF(COUNTIFS(Cronograma!$H$11:$H$45,$A15,Cronograma!$C$11:$C$45,T$6,Cronograma!$B$11:$B$45,"1.ª visita")>0,"1.ª","2.ª")) | U15: =COUNTIF(Cronograma!$H$11:$H$45,$A15) -> 2
A16: PS.02 | B16: Gestión Documental | C16: Jefatura de la Unidad de Trámite Documentario y Archivo | D16: =IF(COUNTIFS(Cronograma!$H$11:$H$45,$A16,Cronograma!$C$11:$C$45,D$6)=0,"",IF(COUNTIFS(Cronograma!$H$11:$H$45,$A16,Cronograma!$C$11:$C$45,D$6,Cronograma!$B$11:$B$45,"1.ª visita")>0,"1.ª","2.ª")) | E16: =IF(COUNTIFS(Cronograma!$H$11:$H$45,$A16,Cronograma!$C$11:$C$45,E$6)=0,"",IF(COUNTIFS(Cronograma!$H$11:$H$45,$A16,Cronograma!$C$11:$C$45,E$6,Cronograma!$B$11:$B$45,"1.ª visita")>0,"1.ª","2.ª")) | F16: =IF(COUNTIFS(Cronograma!$H$11:$H$45,$A16,Cronograma!$C$11:$C$45,F$6)=0,"",IF(COUNTIFS(Cronograma!$H$11:$H$45,$A16,Cronograma!$C$11:$C$45,F$6,Cronograma!$B$11:$B$45,"1.ª visita")>0,"1.ª","2.ª")) | G16: =IF(COUNTIFS(Cronograma!$H$11:$H$45,$A16,Cronograma!$C$11:$C$45,G$6)=0,"",IF(COUNTIFS(Cronograma!$H$11:$H$45,$A16,Cronograma!$C$11:$C$45,G$6,Cronograma!$B$11:$B$45,"1.ª visita")>0,"1.ª","2.ª")) | H16: =IF(COUNTIFS(Cronograma!$H$11:$H$45,$A16,Cronograma!$C$11:$C$45,H$6)=0,"",IF(COUNTIFS(Cronograma!$H$11:$H$45,$A16,Cronograma!$C$11:$C$45,H$6,Cronograma!$B$11:$B$45,"1.ª visita")>0,"1.ª","2.ª")) | I16: =IF(COUNTIFS(Cronograma!$H$11:$H$45,$A16,Cronograma!$C$11:$C$45,I$6)=0,"",IF(COUNTIFS(Cronograma!$H$11:$H$45,$A16,Cronograma!$C$11:$C$45,I$6,Cronograma!$B$11:$B$45,"1.ª visita")>0,"1.ª","2.ª")) -> 1.ª | J16: =IF(COUNTIFS(Cronograma!$H$11:$H$45,$A16,Cronograma!$C$11:$C$45,J$6)=0,"",IF(COUNTIFS(Cronograma!$H$11:$H$45,$A16,Cronograma!$C$11:$C$45,J$6,Cronograma!$B$11:$B$45,"1.ª visita")>0,"1.ª","2.ª")) | K16: =IF(COUNTIFS(Cronograma!$H$11:$H$45,$A16,Cronograma!$C$11:$C$45,K$6)=0,"",IF(COUNTIFS(Cronograma!$H$11:$H$45,$A16,Cronograma!$C$11:$C$45,K$6,Cronograma!$B$11:$B$45,"1.ª visita")>0,"1.ª","2.ª")) | ... T16: =IF(COUNTIFS(Cronograma!$H$11:$H$45,$A16,Cronograma!$C$11:$C$45,T$6)=0,"",IF(COUNTIFS(Cronograma!$H$11:$H$45,$A16,Cronograma!$C$11:$C$45,T$6,Cronograma!$B$11:$B$45,"1.ª visita")>0,"1.ª","2.ª")) | U16: =COUNTIF(Cronograma!$H$11:$H$45,$A16) -> 2
A17: PS.03 | B17: Gestión de Bienestar Integral | C17: Jefatura de la Unidad de Bienestar | D17: =IF(COUNTIFS(Cronograma!$H$11:$H$45,$A17,Cronograma!$C$11:$C$45,D$6)=0,"",IF(COUNTIFS(Cronograma!$H$11:$H$45,$A17,Cronograma!$C$11:$C$45,D$6,Cronograma!$B$11:$B$45,"1.ª visita")>0,"1.ª","2.ª")) | E17: =IF(COUNTIFS(Cronograma!$H$11:$H$45,$A17,Cronograma!$C$11:$C$45,E$6)=0,"",IF(COUNTIFS(Cronograma!$H$11:$H$45,$A17,Cronograma!$C$11:$C$45,E$6,Cronograma!$B$11:$B$45,"1.ª visita")>0,"1.ª","2.ª")) | F17: =IF(COUNTIFS(Cronograma!$H$11:$H$45,$A17,Cronograma!$C$11:$C$45,F$6)=0,"",IF(COUNTIFS(Cronograma!$H$11:$H$45,$A17,Cronograma!$C$11:$C$45,F$6,Cronograma!$B$11:$B$45,"1.ª visita")>0,"1.ª","2.ª")) | G17: =IF(COUNTIFS(Cronograma!$H$11:$H$45,$A17,Cronograma!$C$11:$C$45,G$6)=0,"",IF(COUNTIFS(Cronograma!$H$11:$H$45,$A17,Cronograma!$C$11:$C$45,G$6,Cronograma!$B$11:$B$45,"1.ª visita")>0,"1.ª","2.ª")) | H17: =IF(COUNTIFS(Cronograma!$H$11:$H$45,$A17,Cronograma!$C$11:$C$45,H$6)=0,"",IF(COUNTIFS(Cronograma!$H$11:$H$45,$A17,Cronograma!$C$11:$C$45,H$6,Cronograma!$B$11:$B$45,"1.ª visita")>0,"1.ª","2.ª")) | I17: =IF(COUNTIFS(Cronograma!$H$11:$H$45,$A17,Cronograma!$C$11:$C$45,I$6)=0,"",IF(COUNTIFS(Cronograma!$H$11:$H$45,$A17,Cronograma!$C$11:$C$45,I$6,Cronograma!$B$11:$B$45,"1.ª visita")>0,"1.ª","2.ª")) -> 1.ª | J17: =IF(COUNTIFS(Cronograma!$H$11:$H$45,$A17,Cronograma!$C$11:$C$45,J$6)=0,"",IF(COUNTIFS(Cronograma!$H$11:$H$45,$A17,Cronograma!$C$11:$C$45,J$6,Cronograma!$B$11:$B$45,"1.ª visita")>0,"1.ª","2.ª")) | K17: =IF(COUNTIFS(Cronograma!$H$11:$H$45,$A17,Cronograma!$C$11:$C$45,K$6)=0,"",IF(COUNTIFS(Cronograma!$H$11:$H$45,$A17,Cronograma!$C$11:$C$45,K$6,Cronograma!$B$11:$B$45,"1.ª visita")>0,"1.ª","2.ª")) | ... T17: =IF(COUNTIFS(Cronograma!$H$11:$H$45,$A17,Cronograma!$C$11:$C$45,T$6)=0,"",IF(COUNTIFS(Cronograma!$H$11:$H$45,$A17,Cronograma!$C$11:$C$45,T$6,Cronograma!$B$11:$B$45,"1.ª visita")>0,"1.ª","2.ª")) | U17: =COUNTIF(Cronograma!$H$11:$H$45,$A17) -> 2
A18: PS.04 | B18: Gestión de Recursos Económicos | C18: Jefatura de la Unidad de Economía | D18: =IF(COUNTIFS(Cronograma!$H$11:$H$45,$A18,Cronograma!$C$11:$C$45,D$6)=0,"",IF(COUNTIFS(Cronograma!$H$11:$H$45,$A18,Cronograma!$C$11:$C$45,D$6,Cronograma!$B$11:$B$45,"1.ª visita")>0,"1.ª","2.ª")) | E18: =IF(COUNTIFS(Cronograma!$H$11:$H$45,$A18,Cronograma!$C$11:$C$45,E$6)=0,"",IF(COUNTIFS(Cronograma!$H$11:$H$45,$A18,Cronograma!$C$11:$C$45,E$6,Cronograma!$B$11:$B$45,"1.ª visita")>0,"1.ª","2.ª")) | F18: =IF(COUNTIFS(Cronograma!$H$11:$H$45,$A18,Cronograma!$C$11:$C$45,F$6)=0,"",IF(COUNTIFS(Cronograma!$H$11:$H$45,$A18,Cronograma!$C$11:$C$45,F$6,Cronograma!$B$11:$B$45,"1.ª visita")>0,"1.ª","2.ª")) | G18: =IF(COUNTIFS(Cronograma!$H$11:$H$45,$A18,Cronograma!$C$11:$C$45,G$6)=0,"",IF(COUNTIFS(Cronograma!$H$11:$H$45,$A18,Cronograma!$C$11:$C$45,G$6,Cronograma!$B$11:$B$45,"1.ª visita")>0,"1.ª","2.ª")) | H18: =IF(COUNTIFS(Cronograma!$H$11:$H$45,$A18,Cronograma!$C$11:$C$45,H$6)=0,"",IF(COUNTIFS(Cronograma!$H$11:$H$45,$A18,Cronograma!$C$11:$C$45,H$6,Cronograma!$B$11:$B$45,"1.ª visita")>0,"1.ª","2.ª")) | I18: =IF(COUNTIFS(Cronograma!$H$11:$H$45,$A18,Cronograma!$C$11:$C$45,I$6)=0,"",IF(COUNTIFS(Cronograma!$H$11:$H$45,$A18,Cronograma!$C$11:$C$45,I$6,Cronograma!$B$11:$B$45,"1.ª visita")>0,"1.ª","2.ª")) | J18: =IF(COUNTIFS(Cronograma!$H$11:$H$45,$A18,Cronograma!$C$11:$C$45,J$6)=0,"",IF(COUNTIFS(Cronograma!$H$11:$H$45,$A18,Cronograma!$C$11:$C$45,J$6,Cronograma!$B$11:$B$45,"1.ª visita")>0,"1.ª","2.ª")) -> 1.ª | K18: =IF(COUNTIFS(Cronograma!$H$11:$H$45,$A18,Cronograma!$C$11:$C$45,K$6)=0,"",IF(COUNTIFS(Cronograma!$H$11:$H$45,$A18,Cronograma!$C$11:$C$45,K$6,Cronograma!$B$11:$B$45,"1.ª visita")>0,"1.ª","2.ª")) | ... T18: =IF(COUNTIFS(Cronograma!$H$11:$H$45,$A18,Cronograma!$C$11:$C$45,T$6)=0,"",IF(COUNTIFS(Cronograma!$H$11:$H$45,$A18,Cronograma!$C$11:$C$45,T$6,Cronograma!$B$11:$B$45,"1.ª visita")>0,"1.ª","2.ª")) | U18: =COUNTIF(Cronograma!$H$11:$H$45,$A18) -> 2
A19: PS.05 | B19: Gestión de Recursos Humanos | C19: Jefatura de la Unidad de Personal | D19: =IF(COUNTIFS(Cronograma!$H$11:$H$45,$A19,Cronograma!$C$11:$C$45,D$6)=0,"",IF(COUNTIFS(Cronograma!$H$11:$H$45,$A19,Cronograma!$C$11:$C$45,D$6,Cronograma!$B$11:$B$45,"1.ª visita")>0,"1.ª","2.ª")) | E19: =IF(COUNTIFS(Cronograma!$H$11:$H$45,$A19,Cronograma!$C$11:$C$45,E$6)=0,"",IF(COUNTIFS(Cronograma!$H$11:$H$45,$A19,Cronograma!$C$11:$C$45,E$6,Cronograma!$B$11:$B$45,"1.ª visita")>0,"1.ª","2.ª")) | F19: =IF(COUNTIFS(Cronograma!$H$11:$H$45,$A19,Cronograma!$C$11:$C$45,F$6)=0,"",IF(COUNTIFS(Cronograma!$H$11:$H$45,$A19,Cronograma!$C$11:$C$45,F$6,Cronograma!$B$11:$B$45,"1.ª visita")>0,"1.ª","2.ª")) | G19: =IF(COUNTIFS(Cronograma!$H$11:$H$45,$A19,Cronograma!$C$11:$C$45,G$6)=0,"",IF(COUNTIFS(Cronograma!$H$11:$H$45,$A19,Cronograma!$C$11:$C$45,G$6,Cronograma!$B$11:$B$45,"1.ª visita")>0,"1.ª","2.ª")) | H19: =IF(COUNTIFS(Cronograma!$H$11:$H$45,$A19,Cronograma!$C$11:$C$45,H$6)=0,"",IF(COUNTIFS(Cronograma!$H$11:$H$45,$A19,Cronograma!$C$11:$C$45,H$6,Cronograma!$B$11:$B$45,"1.ª visita")>0,"1.ª","2.ª")) | I19: =IF(COUNTIFS(Cronograma!$H$11:$H$45,$A19,Cronograma!$C$11:$C$45,I$6)=0,"",IF(COUNTIFS(Cronograma!$H$11:$H$45,$A19,Cronograma!$C$11:$C$45,I$6,Cronograma!$B$11:$B$45,"1.ª visita")>0,"1.ª","2.ª")) | J19: =IF(COUNTIFS(Cronograma!$H$11:$H$45,$A19,Cronograma!$C$11:$C$45,J$6)=0,"",IF(COUNTIFS(Cronograma!$H$11:$H$45,$A19,Cronograma!$C$11:$C$45,J$6,Cronograma!$B$11:$B$45,"1.ª visita")>0,"1.ª","2.ª")) -> 1.ª | K19: =IF(COUNTIFS(Cronograma!$H$11:$H$45,$A19,Cronograma!$C$11:$C$45,K$6)=0,"",IF(COUNTIFS(Cronograma!$H$11:$H$45,$A19,Cronograma!$C$11:$C$45,K$6,Cronograma!$B$11:$B$45,"1.ª visita")>0,"1.ª","2.ª")) | ... T19: =IF(COUNTIFS(Cronograma!$H$11:$H$45,$A19,Cronograma!$C$11:$C$45,T$6)=0,"",IF(COUNTIFS(Cronograma!$H$11:$H$45,$A19,Cronograma!$C$11:$C$45,T$6,Cronograma!$B$11:$B$45,"1.ª visita")>0,"1.ª","2.ª")) | U19: =COUNTIF(Cronograma!$H$11:$H$45,$A19) -> 2
A20: PS.06 | B20: Gestión de Abastecimiento y Servicios | C20: Jefatura de la Unidad de Servicios Generales, Operaciones y Mantenimiento | D20: =IF(COUNTIFS(Cronograma!$H$11:$H$45,$A20,Cronograma!$C$11:$C$45,D$6)=0,"",IF(COUNTIFS(Cronograma!$H$11:$H$45,$A20,Cronograma!$C$11:$C$45,D$6,Cronograma!$B$11:$B$45,"1.ª visita")>0,"1.ª","2.ª")) | E20: =IF(COUNTIFS(Cronograma!$H$11:$H$45,$A20,Cronograma!$C$11:$C$45,E$6)=0,"",IF(COUNTIFS(Cronograma!$H$11:$H$45,$A20,Cronograma!$C$11:$C$45,E$6,Cronograma!$B$11:$B$45,"1.ª visita")>0,"1.ª","2.ª")) | F20: =IF(COUNTIFS(Cronograma!$H$11:$H$45,$A20,Cronograma!$C$11:$C$45,F$6)=0,"",IF(COUNTIFS(Cronograma!$H$11:$H$45,$A20,Cronograma!$C$11:$C$45,F$6,Cronograma!$B$11:$B$45,"1.ª visita")>0,"1.ª","2.ª")) | G20: =IF(COUNTIFS(Cronograma!$H$11:$H$45,$A20,Cronograma!$C$11:$C$45,G$6)=0,"",IF(COUNTIFS(Cronograma!$H$11:$H$45,$A20,Cronograma!$C$11:$C$45,G$6,Cronograma!$B$11:$B$45,"1.ª visita")>0,"1.ª","2.ª")) | H20: =IF(COUNTIFS(Cronograma!$H$11:$H$45,$A20,Cronograma!$C$11:$C$45,H$6)=0,"",IF(COUNTIFS(Cronograma!$H$11:$H$45,$A20,Cronograma!$C$11:$C$45,H$6,Cronograma!$B$11:$B$45,"1.ª visita")>0,"1.ª","2.ª")) | I20: =IF(COUNTIFS(Cronograma!$H$11:$H$45,$A20,Cronograma!$C$11:$C$45,I$6)=0,"",IF(COUNTIFS(Cronograma!$H$11:$H$45,$A20,Cronograma!$C$11:$C$45,I$6,Cronograma!$B$11:$B$45,"1.ª visita")>0,"1.ª","2.ª")) | J20: =IF(COUNTIFS(Cronograma!$H$11:$H$45,$A20,Cronograma!$C$11:$C$45,J$6)=0,"",IF(COUNTIFS(Cronograma!$H$11:$H$45,$A20,Cronograma!$C$11:$C$45,J$6,Cronograma!$B$11:$B$45,"1.ª visita")>0,"1.ª","2.ª")) -> 1.ª | K20: =IF(COUNTIFS(Cronograma!$H$11:$H$45,$A20,Cronograma!$C$11:$C$45,K$6)=0,"",IF(COUNTIFS(Cronograma!$H$11:$H$45,$A20,Cronograma!$C$11:$C$45,K$6,Cronograma!$B$11:$B$45,"1.ª visita")>0,"1.ª","2.ª")) | ... T20: =IF(COUNTIFS(Cronograma!$H$11:$H$45,$A20,Cronograma!$C$11:$C$45,T$6)=0,"",IF(COUNTIFS(Cronograma!$H$11:$H$45,$A20,Cronograma!$C$11:$C$45,T$6,Cronograma!$B$11:$B$45,"1.ª visita")>0,"1.ª","2.ª")) | U20: =COUNTIF(Cronograma!$H$11:$H$45,$A20) -> 2
... A23: PS.10 | B23: Gestión de la Comunicación | C23: Oficina de Imagen de la FPSIC (encargatura) | D23: =IF(COUNTIFS(Cronograma!$H$11:$H$45,$A23,Cronograma!$C$11:$C$45,D$6)=0,"",IF(COUNTIFS(Cronograma!$H$11:$H$45,$A23,Cronograma!$C$11:$C$45,D$6,Cronograma!$B$11:$B$45,"1.ª visita")>0,"1.ª","2.ª")) | E23: =IF(COUNTIFS(Cronograma!$H$11:$H$45,$A23,Cronograma!$C$11:$C$45,E$6)=0,"",IF(COUNTIFS(Cronograma!$H$11:$H$45,$A23,Cronograma!$C$11:$C$45,E$6,Cronograma!$B$11:$B$45,"1.ª visita")>0,"1.ª","2.ª")) | F23: =IF(COUNTIFS(Cronograma!$H$11:$H$45,$A23,Cronograma!$C$11:$C$45,F$6)=0,"",IF(COUNTIFS(Cronograma!$H$11:$H$45,$A23,Cronograma!$C$11:$C$45,F$6,Cronograma!$B$11:$B$45,"1.ª visita")>0,"1.ª","2.ª")) | G23: =IF(COUNTIFS(Cronograma!$H$11:$H$45,$A23,Cronograma!$C$11:$C$45,G$6)=0,"",IF(COUNTIFS(Cronograma!$H$11:$H$45,$A23,Cronograma!$C$11:$C$45,G$6,Cronograma!$B$11:$B$45,"1.ª visita")>0,"1.ª","2.ª")) | H23: =IF(COUNTIFS(Cronograma!$H$11:$H$45,$A23,Cronograma!$C$11:$C$45,H$6)=0,"",IF(COUNTIFS(Cronograma!$H$11:$H$45,$A23,Cronograma!$C$11:$C$45,H$6,Cronograma!$B$11:$B$45,"1.ª visita")>0,"1.ª","2.ª")) | I23: =IF(COUNTIFS(Cronograma!$H$11:$H$45,$A23,Cronograma!$C$11:$C$45,I$6)=0,"",IF(COUNTIFS(Cronograma!$H$11:$H$45,$A23,Cronograma!$C$11:$C$45,I$6,Cronograma!$B$11:$B$45,"1.ª visita")>0,"1.ª","2.ª")) | J23: =IF(COUNTIFS(Cronograma!$H$11:$H$45,$A23,Cronograma!$C$11:$C$45,J$6)=0,"",IF(COUNTIFS(Cronograma!$H$11:$H$45,$A23,Cronograma!$C$11:$C$45,J$6,Cronograma!$B$11:$B$45,"1.ª visita")>0,"1.ª","2.ª")) | K23: =IF(COUNTIFS(Cronograma!$H$11:$H$45,$A23,Cronograma!$C$11:$C$45,K$6)=0,"",IF(COUNTIFS(Cronograma!$H$11:$H$45,$A23,Cronograma!$C$11:$C$45,K$6,Cronograma!$B$11:$B$45,"1.ª visita")>0,"1.ª","2.ª")) | ... T23: =IF(COUNTIFS(Cronograma!$H$11:$H$45,$A23,Cronograma!$C$11:$C$45,T$6)=0,"",IF(COUNTIFS(Cronograma!$H$11:$H$45,$A23,Cronograma!$C$11:$C$45,T$6,Cronograma!$B$11:$B$45,"1.ª visita")>0,"1.ª","2.ª")) -> 2.ª | U23: =COUNTIF(Cronograma!$H$11:$H$45,$A23) -> 2
C24: Sesiones del día | D24: =COUNTIFS(Cronograma!$C$11:$C$45,D$6,Cronograma!$H$11:$H$45,"?*") -> 0 | E24: =COUNTIFS(Cronograma!$C$11:$C$45,E$6,Cronograma!$H$11:$H$45,"?*") -> 3 | F24: =COUNTIFS(Cronograma!$C$11:$C$45,F$6,Cronograma!$H$11:$H$45,"?*") -> 3 | G24: =COUNTIFS(Cronograma!$C$11:$C$45,G$6,Cronograma!$H$11:$H$45,"?*") -> 0 | H24: =COUNTIFS(Cronograma!$C$11:$C$45,H$6,Cronograma!$H$11:$H$45,"?*") -> 0 | I24: =COUNTIFS(Cronograma!$C$11:$C$45,I$6,Cronograma!$H$11:$H$45,"?*") -> 3 | J24: =COUNTIFS(Cronograma!$C$11:$C$45,J$6,Cronograma!$H$11:$H$45,"?*") -> 3 | K24: =COUNTIFS(Cronograma!$C$11:$C$45,K$6,Cronograma!$H$11:$H$45,"?*") -> 2 | ... T24: =COUNTIFS(Cronograma!$C$11:$C$45,T$6,Cronograma!$H$11:$H$45,"?*") -> 1 | U24: =SUM(U9:U23) -> 30

Sheet Resumen por proceso
A1: RESUMEN POR PROCESO
A2: Mapa de procesos estándar (PE, PM y PS) · cobertura de visitas en la FPSIC
A3: Universidad Nacional Mayor de San Marcos · Oficina General de Planificación · Oficina de Racionalización | Proyecto P01 · Plan P01-PG-F2 v1.1 | Versión 2.0 del cronograma · revisada el 15/10/2026
A6: Código | B6: Proceso | C6: Unidad orgánica | D6: Responsable | E6: 1.ª visita | F6: 2.ª visita | G6: Sesiones | H6: Horas | I6: Estado
A7: PE.01 | B7: Gestión Estratégica | C7: Jefatura de la Unidad de Planificación, Presupuesto y Racionalización (UPPR) | D7: Rosa Guillermina Coaila Moreno | E7: =_xlfn.MINIFS(Cronograma!$C$11:$C$45,Cronograma!$H$11:$H$45,$A7,Cronograma!$B$11:$B$45,"1.ª visita") -> 46316 | F7: =_xlfn.MINIFS(Cronograma!$C$11:$C$45,Cronograma!$H$11:$H$45,$A7,Cronograma!$B$11:$B$45,"2.ª visita") -> 46329 | G7: =COUNTIF(Cronograma!$H$11:$H$45,$A7) -> 2 | H7: =SUMIF(Cronograma!$H$11:$H$45,$A7,Cronograma!$G$11:$G$45)*24 -> 3.3333333 | I7: =IF(G7=0,"Sin visitas",IF(G7=1,"Falta 2.ª visita","Dos visitas")) -> Dos visitas
A8: PE.02 | B8: Gestión de la Calidad y Mejora Continua | C8: Jefatura de la Oficina de Calidad Académica y Acreditación | D8: Susana Consuelo Roggero Rebaza | E8: =_xlfn.MINIFS(Cronograma!$C$11:$C$45,Cronograma!$H$11:$H$45,$A8,Cronograma!$B$11:$B$45,"1.ª visita") -> 46316 | F8: =_xlfn.MINIFS(Cronograma!$C$11:$C$45,Cronograma!$H$11:$H$45,$A8,Cronograma!$B$11:$B$45,"2.ª visita") -> 46329 | G8: =COUNTIF(Cronograma!$H$11:$H$45,$A8) -> 2 | H8: =SUMIF(Cronograma!$H$11:$H$45,$A8,Cronograma!$G$11:$G$45)*24 -> 3.3333333 | I8: =IF(G8=0,"Sin visitas",IF(G8=1,"Falta 2.ª visita","Dos visitas")) -> Dos visitas
A9: PE.03 | B9: Gestión de Relaciones Interinstitucionales | C9: Dirección de la Escuela Profesional de Psicología Dirección de la Escuela Profesional de Psicología Organizacional y de la Gestión Humana Jefatura de la Unidad de Prácticas Preprofesionales | D9: Carmen Leni Alvarez Taco Abel Cuzcano Zapata Jorge Luis Soto Mateo | E9: =_xlfn.MINIFS(Cronograma!$C$11:$C$45,Cronograma!$H$11:$H$45,$A9,Cronograma!$B$11:$B$45,"1.ª visita") -> 46316 | F9: =_xlfn.MINIFS(Cronograma!$C$11:$C$45,Cronograma!$H$11:$H$45,$A9,Cronograma!$B$11:$B$45,"2.ª visita") -> 46329 | G9: =COUNTIF(Cronograma!$H$11:$H$45,$A9) -> 2 | H9: =SUMIF(Cronograma!$H$11:$H$45,$A9,Cronograma!$G$11:$G$45)*24 -> 3.3333333 | I9: =IF(G9=0,"Sin visitas",IF(G9=1,"Falta 2.ª visita","Dos visitas")) -> Dos visitas
A10: PM.01 | B10: Gestión de la Formación Académica | C10: Vicedecanato Académico de Pregrado | D10: Elisa Beatriz Yanac Reynoso | E10: =_xlfn.MINIFS(Cronograma!$C$11:$C$45,Cronograma!$H$11:$H$45,$A10,Cronograma!$B$11:$B$45,"1.ª visita") -> 46317 | F10: =_xlfn.MINIFS(Cronograma!$C$11:$C$45,Cronograma!$H$11:$H$45,$A10,Cronograma!$B$11:$B$45,"2.ª visita") -> 46330 | G10: =COUNTIF(Cronograma!$H$11:$H$45,$A10) -> 2 | H10: =SUMIF(Cronograma!$H$11:$H$45,$A10,Cronograma!$G$11:$G$45)*24 -> 3.3333333 | I10: =IF(G10=0,"Sin visitas",IF(G10=1,"Falta 2.ª visita","Dos visitas")) -> Dos visitas
A11: PM.02 | B11: Gestión de la Investigación | C11: Vicedecanato de Investigación y Posgrado | D11: Carlos Alberto Arenas Iparraguirre | E11: =_xlfn.MINIFS(Cronograma!$C$11:$C$45,Cronograma!$H$11:$H$45,$A11,Cronograma!$B$11:$B$45,"1.ª visita") -> 46317 | F11: =_xlfn.MINIFS(Cronograma!$C$11:$C$45,Cronograma!$H$11:$H$45,$A11,Cronograma!$B$11:$B$45,"2.ª visita") -> 46330 | G11: =COUNTIF(Cronograma!$H$11:$H$45,$A11) -> 2 | H11: =SUMIF(Cronograma!$H$11:$H$45,$A11,Cronograma!$G$11:$G$45)*24 -> 3.3333333 | I11: =IF(G11=0,"Sin visitas",IF(G11=1,"Falta 2.ª visita","Dos visitas")) -> Dos visitas
